Workbook

Sheet FAR18
A1: FAR MRC Management Services
A3: Ledger Accounts: MARCH 2017 - FEBRUARY 2018
A4: Date | B4: Reference | C4: Description | D4: Cost (ExVAT) | E4: Additions | F4: Disposals | G4: Total | H4: Per | I4: 42825 | J4: 42835 | K4: 42865 | L4: 42896 | M4: 42926 | N4: 42957 | O4: 42988 | P4: 43018 | Q4: 43049 | R4: 43079 | S4: 43110 | T4: 43141 | U4: Depn for Year | V4: Accum Depn | W4: NBV 2018
A6: 6100>020 (Computer Equipment>Cost) | I6: =+A6 -> 6100>020 (Computer Equipment>Cost)
H7: 3
A8: 42825 | B8: 18431 | C8: SevenC - 2 X HP Desktop CPU (AP & EM) | D8: 16077.6 | G8: =+D8+E8-F8 -> 16077.6 | I8: =+$G8/$H$7/365*(31-31) -> 0 | J8: =+$G8/$H$7/12 -> 446.6 | K8: =+$G8/$H$7/12 -> 446.6 | L8: =+$G8/$H$7/12 -> 446.6 | M8: =+$G8/$H$7/12 -> 446.6 | N8: =+$G8/$H$7/12 -> 446.6 | O8: =+$G8/$H$7/12 -> 446.6 | P8: =+$G8/$H$7/12 -> 446.6 | Q8: =+$G8/$H$7/12 -> 446.6 | ... T8: =+$G8/$H$7/12 -> 446.6 | U8: =SUM(I8:T8) -> 4912.6 | V8: =U8 -> 4912.6 | W8: =+G8-V8 -> 11165
A9: 42825 | B9: 18431 | C9: SevenC - HP ProBook 450 G4 Laptop (JN) | D9: 10078.8 | G9: =+D9+E9-F9 -> 10078.8 | I9: =+$G9/$H$7/365*(31-31) -> 0 | J9: =+$G9/$H$7/12 -> 279.96667 | K9: =+$G9/$H$7/12 -> 279.96667 | L9: =+$G9/$H$7/12 -> 279.96667 | M9: =+$G9/$H$7/12 -> 279.96667 | N9: =+$G9/$H$7/12 -> 279.96667 | O9: =+$G9/$H$7/12 -> 279.96667 | P9: =+$G9/$H$7/12 -> 279.96667 | Q9: =+$G9/$H$7/12 -> 279.96667 | ... T9: =+$G9/$H$7/12 -> 279.96667 | U9: =SUM(I9:T9) -> 3079.6333 | V9: =U9 -> 3079.6333 | W9: =+G9-V9 -> 6999.1667
A10: 43046 | B10: INA90085 | C10: Heart FM - CBA/Polycom System / VC | D10: 52651 | G10: =+D10+E10-F10 -> 52651 | I10: 0 | J10: 0 | K10: 0 | L10: 0 | M10: 0 | N10: 0 | O10: 0 | P10: 0 | Q10: =+$G10/$H$7/365*(30-7) -> 1105.9114 | R10: =+$G10/$H$7/12 -> 1462.5278 | S10: =+$G10/$H$7/12 -> 1462.5278 | T10: =+$G10/$H$7/12 -> 1462.5278 | U10: =SUM(I10:T10) -> 5493.4947 | V10: =U10 -> 5493.4947 | W10: =+G10-V10 -> 47157.505
D12: =SUM(D6:D11) -> 78807.4 | E12: =SUM(E6:E11) -> 0 | G12: =SUM(G8:G11) -> 78807.4 | I12: =SUM(I8:I11) -> 0 | J12: =SUM(J8:J11) -> 726.56667 | K12: =SUM(K8:K11) -> 726.56667 | L12: =SUM(L8:L11) -> 726.56667 | M12: =SUM(M8:M11) -> 726.56667 | N12: =SUM(N8:N11) -> 726.56667 | O12: =SUM(O8:O11) -> 726.56667 | P12: =SUM(P8:P11) -> 726.56667 | ... W12: =SUM(W8:W11) -> 65321.672
A14: Date | B14: Reference | C14: Description | D14: Cost | E14: Add | F14: Disp | G14: Total | H14: Per | I14: 42825 | J14: 42855 | K14: 42886 | L14: 42916 | M14: 42947 | N14: 42978 | O14: 43008 | P14: 43039 | Q14: 43069 | R14: 43100 | S14: 43131 | T14: 43159 | U14: Depn for Year | V14: Accum Depn | W14: NBV 2018
A15: 6200>020 (Furniture & Fittings>Cost) | H15: 6 | I15: =+A15 -> 6200>020 (Furniture & Fittings>Cost)
A17: 42836 | B17: 30110 | C17: BFS - 15 X Roberto High Back Chairs | D17: 52250 | G17: =+D17+E17-F17 -> 52250 | I17: 0 | J17: =+$G17/$H$15/365*(30-11) -> 453.3105 | K17: =+$G17/$H$15/12 -> 725.69444 | L17: =+$G17/$H$15/12 -> 725.69444 | M17: =+$G17/$H$15/12 -> 725.69444 | N17: =+$G17/$H$15/12 -> 725.69444 | O17: =+$G17/$H$15/12 -> 725.69444 | P17: =+$G17/$H$15/12 -> 725.69444 | Q17: =+$G17/$H$15/12 -> 725.69444 | R17: =+$G17/$H$15/12 -> 725.69444 | ... T17: =+$G17/$H$15/12 -> 725.69444 | U17: =SUM(I17:T17) -> 7710.2549 | V17: =U17 -> 7710.2549 | W17: =+G17-V17 -> 44539.745
D19: =SUM(D15:D18) -> 52250 | E19: =SUM(E15:E18) -> 0 | F19: =SUM(F15:F18) -> 0 | G19: =SUM(D19:F19) -> 52250 | I19: =SUM(I17:I18) -> 0 | J19: =SUM(J17:J18) -> 453.3105 | K19: =SUM(K17:K18) -> 725.69444 | L19: =SUM(L17:L18) -> 725.69444 | M19: =SUM(M17:M18) -> 725.69444 | N19: =SUM(N17:N18) -> 725.69444 | O19: =SUM(O17:O18) -> 725.69444 | P19: =SUM(P17:P18) -> 725.69444 | ... W19: =SUM(W17:W18) -> 44539.745
A21: Date | B21: Reference | C21: Description | D21: Cost | E21: Add | F21: Disp | G21: Total | H21: Per | I21: 42825 | J21: 42855 | K21: 42886 | L21: 42916 | M21: 42947 | N21: 42978 | O21: 43008 | P21: 43039 | Q21: 43069 | R21: 43100 | S21: 43131 | T21: 43159 | U21: Depn for Year | V21: Accum Depn | W21: NBV 2018
A22: 6300>020 (Motor Vehicles>Cost) | H22: 5 | I22: =+A22 -> 6300>020 (Motor Vehicles>Cost)
A24: 42860 | B24: 89009640 | C24: Rivonia Toyota: Corolla Quest 1.6 AT | D24: 255969.92 | G24: =+D24+E24-F24 -> 255969.92 | I24: 0 | J24: 0 | K24: =+$G24/$H$22/365*(31-5) -> 3646.6948 | L24: =+$G24/$H$22/12 -> 4266.1653 | M24: =+$G24/$H$22/12 -> 4266.1653 | N24: =+$G24/$H$22/12 -> 4266.1653 | O24: =+$G24/$H$22/12 -> 4266.1653 | P24: =+$G24/$H$22/12 -> 4266.1653 | Q24: =+$G24/$H$22/12 -> 4266.1653 | R24: =+$G24/$H$22/12 -> 4266.1653 | S24: =+$G24/$H$22/12 -> 4266.1653 | T24: =+$G24/$H$22/12 -> 4266.1653 | U24: =SUM(I24:T24) -> 42042.183 | V24: =U24 -> 42042.183 | W24: =+G24-V24 -> 213927.74
D26: =SUM(D24) -> 255969.92 | E26: =SUM(E24) -> 0 | F26: =SUM(F24) -> 0 | G26: =SUM(D26:F26) -> 255969.92 | I26: =SUM(I24) -> 0 | J26: =SUM(J24) -> 0 | K26: =SUM(K24) -> 3646.6948 | L26: =SUM(L24) -> 4266.1653 | M26: =SUM(M24) -> 4266.1653 | N26: =SUM(N24) -> 4266.1653 | O26: =SUM(O24) -> 4266.1653 | P26: =SUM(P24) -> 4266.1653 | ... W26: =SUM(W24) -> 213927.74
A28: Grand Total | D28: =D12+D19+D26 -> 387027.32 | E28: =E12+E19+E26 -> 0 | F28: =F12+F19+F26 -> 0 | G28: =G12+G19+G26 -> 387027.32 | I28: =I12+I19+I26 -> 0 | J28: =J12+J19+J26 -> 1179.8772 | K28: =K12+K19+K26 -> 5098.9559 | L28: =L12+L19+L26 -> 5718.4264 | M28: =M12+M19+M26 -> 5718.4264 | N28: =N12+N19+N26 -> 5718.4264 | O28: =O12+O19+O26 -> 5718.4264 | P28: =P12+P19+P26 -> 5718.4264 | ... W28: =W12+W19+W26 -> 323789.15

Sheet FAR19
A1: FAR MRC Management Services
A3: Ledger Accounts: MARCH 2018 - FEBRUARY 2019
A4: Date | B4: Reference | C4: Description | D4: Cost (ExVAT) | E4: Additions | F4: Disp | G4: Total | H4: Per | I4: 43190 | J4: 43220 | K4: 43251 | L4: 43281 | M4: 43312 | N4: 43343 | O4: 43373 | P4: 43404 | Q4: 43434 | R4: 43465 | S4: 43496 | T4: 43524 | U4: Depn for Year | V4: Accum Depn | W4: NBV 2019
A6: 6100>020 (Computer Equipment>Cost) | I6: =+A6 -> 6100>020 (Computer Equipment>Cost)
H7: 3
A8: 42825 | B8: 18431 | C8: SevenC - 2 X HP Desktop CPU (AP & EM) | D8: 16077.6 | G8: =+D8+E8-F8 -> 16077.6 | I8: =+$G8/$H$7/12 -> 446.6 | J8: =+$G8/$H$7/12 -> 446.6 | K8: =+$G8/$H$7/12 -> 446.6 | L8: =+$G8/$H$7/12 -> 446.6 | M8: =+$G8/$H$7/12 -> 446.6 | N8: =+$G8/$H$7/12 -> 446.6 | O8: =+$G8/$H$7/12 -> 446.6 | P8: =+$G8/$H$7/12 -> 446.6 | ... T8: =+$G8/$H$7/12 -> 446.6 | U8: =SUM(I8:T8) -> 5359.2 | V8: =U8+'FAR18'!V8 -> 10271.8 | W8: =+G8-V8 -> 5805.8
A9: 42825 | B9: 18431 | C9: SevenC - HP ProBook 450 G4 Laptop (JN) | D9: 10078.8 | G9: =+D9+E9-F9 -> 10078.8 | I9: =+$G9/$H$7/12 -> 279.96667 | J9: =+$G9/$H$7/12 -> 279.96667 | K9: =+$G9/$H$7/12 -> 279.96667 | L9: =+$G9/$H$7/12 -> 279.96667 | M9: =+$G9/$H$7/12 -> 279.96667 | N9: =+$G9/$H$7/12 -> 279.96667 | O9: =+$G9/$H$7/12 -> 279.96667 | P9: =+$G9/$H$7/12 -> 279.96667 | ... T9: =+$G9/$H$7/12 -> 279.96667 | U9: =SUM(I9:T9) -> 3359.6 | V9: =U9+'FAR18'!V9 -> 6439.2333 | W9: =+G9-V9 -> 3639.5667
A10: 43046 | B10: INA90085 | C10: Heart FM - CBA/Polycom System / VC | D10: 52651 | G10: =+D10+E10-F10 -> 52651 | I10: =+$G10/$H$7/12 -> 1462.5278 | J10: =+$G10/$H$7/12 -> 1462.5278 | K10: =+$G10/$H$7/12 -> 1462.5278 | L10: =+$G10/$H$7/12 -> 1462.5278 | M10: =+$G10/$H$7/12 -> 1462.5278 | N10: =+$G10/$H$7/12 -> 1462.5278 | O10: =+$G10/$H$7/12 -> 1462.5278 | P10: =+$G10/$H$7/12 -> 1462.5278 | ... T10: =+$G10/$H$7/12 -> 1462.5278 | U10: =SUM(I10:T10) -> 17550.333 | V10: =U10+'FAR18'!V10 -> 23043.828 | W10: =+G10-V10 -> 29607.172
A11: 43160 | B11: 21643 | C11: SevenC - 6 X HP Desktop & Keyboards | E11: 92322.7 | G11: =+D11+E11-F11 -> 92322.7 | I11: =+$G11/$H$7/12 -> 2564.5194 | J11: =+$G11/$H$7/12 -> 2564.5194 | K11: =+$G11/$H$7/12 -> 2564.5194 | L11: =+$G11/$H$7/12 -> 2564.5194 | M11: =+$G11/$H$7/12 -> 2564.5194 | N11: =+$G11/$H$7/12 -> 2564.5194 | O11: =+$G11/$H$7/12 -> 2564.5194 | P11: =+$G11/$H$7/12 -> 2564.5194 | ... T11: =+$G11/$H$7/12 -> 2564.5194 | U11: =SUM(I11:T11) -> 30774.233 | V11: =U11 -> 30774.233 | W11: =+G11-V11 -> 61548.467
D13: =SUM(D6:D12) -> 78807.4 | E13: =SUM(E6:E12) -> 92322.7 | G13: =SUM(G8:G12) -> 171130.1 | I13: =SUM(I8:I12) -> 4753.6139 | J13: =SUM(J8:J12) -> 4753.6139 | K13: =SUM(K8:K12) -> 4753.6139 | L13: =SUM(L8:L12) -> 4753.6139 | M13: =SUM(M8:M12) -> 4753.6139 | N13: =SUM(N8:N12) -> 4753.6139 | O13: =SUM(O8:O12) -> 4753.6139 | P13: =SUM(P8:P12) -> 4753.6139 | ... W13: =SUM(W8:W12) -> 100601.01
A15: Date | B15: Reference | C15: Description | D15: Cost | E15: Additions | F15: Disp | G15: Total | H15: Per | I15: 43190 | J15: 43220 | K15: 43251 | L15: 43281 | M15: 43312 | N15: 43343 | O15: 43373 | P15: 43404 | Q15: 43434 | R15: 43465 | S15: 43496 | T15: 43524 | U15: Depn for Year | V15: Accum Depn | W15: NBV 2019
A16: 6200>020 (Furniture & Fittings>Cost) | H16: 6 | I16: =+A16 -> 6200>020 (Furniture & Fittings>Cost)
A18: 42836 | B18: 30110 | C18: BFS - 15 X Roberto High Back Chairs | D18: 52250 | G18: =+D18+E18-F18 -> 52250 | I18: =+$G18/$H$16/12 -> 725.69444 | J18: =+$G18/$H$16/12 -> 725.69444 | K18: =+$G18/$H$16/12 -> 725.69444 | L18: =+$G18/$H$16/12 -> 725.69444 | M18: =+$G18/$H$16/12 -> 725.69444 | N18: =+$G18/$H$16/12 -> 725.69444 | O18: =+$G18/$H$16/12 -> 725.69444 | P18: =+$G18/$H$16/12 -> 725.69444 | ... T18: =+$G18/$H$16/12 -> 725.69444 | U18: =SUM(I18:T18) -> 8708.3333 | V18: =U18+'FAR18'!V17 -> 16418.588 | W18: =+G18-V18 -> 35831.412
A19: 43165 | B19: Piyox-TV | C19: Boardroom TV - Samsung 75" UHD | E19: 44144 | G19: =+D19+E19-F19 -> 44144 | I19: =+$G19/$H$16/365*(31-6) -> 503.92694 | J19: =+$G19/$H$16/12 -> 613.11111 | K19: =+$G19/$H$16/12 -> 613.11111 | L19: =+$G19/$H$16/12 -> 613.11111 | M19: =+$G19/$H$16/12 -> 613.11111 | N19: =+$G19/$H$16/12 -> 613.11111 | O19: =+$G19/$H$16/12 -> 613.11111 | P19: =+$G19/$H$16/12 -> 613.11111 | Q19: =+$G19/$H$16/12 -> 613.11111 | ... T19: =+$G19/$H$16/12 -> 613.11111 | U19: =SUM(I19:T19) -> 7248.1492 | V19: =U19 -> 7248.1492 | W19: =+G19-V19 -> 36895.851
A20: 43179 | B20: 32006 | C20: BFS - 5 X Roberto High Back Chairs | E20: =9715*2 -> 19430 | G20: =+D20+E20-F20 -> 19430 | I20: =+$G20/$H$16/365*(31-20) -> 97.593607 | J20: =+$G20/$H$16/12 -> 269.86111 | K20: =+$G20/$H$16/12 -> 269.86111 | L20: =+$G20/$H$16/12 -> 269.86111 | M20: =+$G20/$H$16/12 -> 269.86111 | N20: =+$G20/$H$16/12 -> 269.86111 | O20: =+$G20/$H$16/12 -> 269.86111 | P20: =+$G20/$H$16/12 -> 269.86111 | Q20: =+$G20/$H$16/12 -> 269.86111 | ... T20: =+$G20/$H$16/12 -> 269.86111 | U20: =SUM(I20:T20) -> 3066.0658 | V20: =U20 -> 3066.0658 | W20: =+G20-V20 -> 16363.934
D22: =SUM(D16:D21) -> 52250 | E22: =SUM(E16:E21) -> 63574 | F22: =SUM(F16:F21) -> 0 | G22: =SUM(D22:F22) -> 115824 | I22: =SUM(I18:I21) -> 1327.215 | J22: =SUM(J18:J21) -> 1608.6667 | K22: =SUM(K18:K21) -> 1608.6667 | L22: =SUM(L18:L21) -> 1608.6667 | M22: =SUM(M18:M21) -> 1608.6667 | N22: =SUM(N18:N21) -> 1608.6667 | O22: =SUM(O18:O21) -> 1608.6667 | P22: =SUM(P18:P21) -> 1608.6667 | ... W22: =SUM(W18:W21) -> 89091.197
A24: Date | B24: Reference | C24: Description | D24: Cost | E24: Additions | F24: Disp | G24: Total | H24: Per | I24: 43190 | J24: 43220 | K24: 43251 | L24: 43281 | M24: 43312 | N24: 43343 | O24: 43373 | P24: 43404 | Q24: 43434 | R24: 43465 | S24: 43496 | T24: 43524 | U24: Depn for Year | V24: Accum Depn | W24: NBV 2019
A25: 6300>020 (Motor Vehicles>Cost) | H25: 5 | I25: =+A25 -> 6300>020 (Motor Vehicles>Cost)
A27: 42860 | B27: 89009640 | C27: Rivonia Toyota: Corolla Quest 1.6 AT | D27: 255969.92 | G27: =+D27+E27-F27 -> 255969.92 | I27: =+$G27/$H$25/12 -> 4266.1653 | J27: =+$G27/$H$25/12 -> 4266.1653 | K27: =+$G27/$H$25/12 -> 4266.1653 | L27: =+$G27/$H$25/12 -> 4266.1653 | M27: =+$G27/$H$25/12 -> 4266.1653 | N27: =+$G27/$H$25/12 -> 4266.1653 | O27: =+$G27/$H$25/12 -> 4266.1653 | P27: =+$G27/$H$25/12 -> 4266.1653 | ... T27: =+$G27/$H$25/12 -> 4266.1653 | U27: =SUM(I27:T27) -> 51193.984 | V27: =U27+'FAR18'!V24 -> 93236.167 | W27: =+G27-V27 -> 162733.75
D29: =SUM(D27) -> 255969.92 | E29: =SUM(E27) -> 0 | F29: =SUM(F27) -> 0 | G29: =SUM(D29:F29) -> 255969.92 | I29: =SUM(I27) -> 4266.1653 | J29: =SUM(J27) -> 4266.1653 | K29: =SUM(K27) -> 4266.1653 | L29: =SUM(L27) -> 4266.1653 | M29: =SUM(M27) -> 4266.1653 | N29: =SUM(N27) -> 4266.1653 | O29: =SUM(O27) -> 4266.1653 | P29: =SUM(P27) -> 4266.1653 | ... W29: =SUM(W27) -> 162733.75
A31: Grand Total | D31: =D13+D22+D29 -> 387027.32 | E31: =E13+E22+E29 -> 155896.7 | F31: =F13+F22+F29 -> 0 | G31: =G13+G22+G29 -> 542924.02 | I31: =I13+I22+I29 -> 10346.994 | J31: =J13+J22+J29 -> 10628.446 | K31: =K13+K22+K29 -> 10628.446 | L31: =L13+L22+L29 -> 10628.446 | M31: =M13+M22+M29 -> 10628.446 | N31: =N13+N22+N29 -> 10628.446 | O31: =O13+O22+O29 -> 10628.446 | P31: =P13+P22+P29 -> 10628.446 | ... W31: =W13+W22+W29 -> 352425.96

Sheet FAR20
A1: FAR MRC Management Services
A3: Ledger Accounts: MARCH 2019 - FEBRUARY 2020
A4: Date | B4: Reference | C4: Description | D4: Cost (ExVAT) | E4: Additions | F4: Disp | G4: Total | H4: Per | I4: 43555 | J4: 43585 | K4: 43616 | L4: 43646 | M4: 43677 | N4: 43708 | O4: 43738 | P4: 43769 | Q4: 43799 | R4: 43830 | S4: 43861 | T4: 43890 | U4: Depn for Year | V4: Accum Depn | W4: NBV 2020
A6: 6100>020 (Computer Equipment>Cost) | I6: =+A6 -> 6100>020 (Computer Equipment>Cost)
H7: 3
A8: 42825 | B8: 18431 | C8: SevenC - 2 X HP Desktop CPU (AP & EM) | D8: ='FAR19'!G8 -> 16077.6 | G8: =+D8+E8-F8 -> 16077.6 | I8: =+$G8/$H$7/12 -> 446.6 | J8: =+$G8/$H$7/12 -> 446.6 | K8: =+$G8/$H$7/12 -> 446.6 | L8: =+$G8/$H$7/12 -> 446.6 | M8: =+$G8/$H$7/12 -> 446.6 | N8: =+$G8/$H$7/12 -> 446.6 | O8: =+$G8/$H$7/12 -> 446.6 | P8: =+$G8/$H$7/12 -> 446.6 | ... T8: =+$G8/$H$7/12 -> 446.6 | U8: =SUM(I8:T8) -> 5359.2 | V8: =U8+'FAR19'!V8 -> 15631 | W8: =+G8-V8 -> 446.6
A9: 42825 | B9: 18431 | C9: SevenC - HP ProBook 450 G4 Laptop (JN) | D9: ='FAR19'!G9 -> 10078.8 | G9: =+D9+E9-F9 -> 10078.8 | I9: =+$G9/$H$7/12 -> 279.96667 | J9: =+$G9/$H$7/12 -> 279.96667 | K9: =+$G9/$H$7/12 -> 279.96667 | L9: =+$G9/$H$7/12 -> 279.96667 | M9: =+$G9/$H$7/12 -> 279.96667 | N9: =+$G9/$H$7/12 -> 279.96667 | O9: =+$G9/$H$7/12 -> 279.96667 | P9: =+$G9/$H$7/12 -> 279.96667 | ... T9: =+$G9/$H$7/12 -> 279.96667 | U9: =SUM(I9:T9) -> 3359.6 | V9: =U9+'FAR19'!V9 -> 9798.8333 | W9: =+G9-V9 -> 279.96667
A10: 43046 | B10: INA90085 | C10: Heart FM - CBA/Polycom System / VC | D10: ='FAR19'!G10 -> 52651 | G10: =+D10+E10-F10 -> 52651 | I10: =+$G10/$H$7/12 -> 1462.5278 | J10: =+$G10/$H$7/12 -> 1462.5278 | K10: =+$G10/$H$7/12 -> 1462.5278 | L10: =+$G10/$H$7/12 -> 1462.5278 | M10: =+$G10/$H$7/12 -> 1462.5278 | N10: =+$G10/$H$7/12 -> 1462.5278 | O10: =+$G10/$H$7/12 -> 1462.5278 | P10: =+$G10/$H$7/12 -> 1462.5278 | ... T10: =+$G10/$H$7/12 -> 1462.5278 | U10: =SUM(I10:T10) -> 17550.333 | V10: =U10+'FAR19'!V10 -> 40594.161 | W10: =+G10-V10 -> 12056.839
A11: 43160 | B11: 21643 | C11: SevenC - 6 X HP Desktop & Keyboards | D11: ='FAR19'!G11 -> 92322.7 | G11: =+D11+E11-F11 -> 92322.7 | I11: =+$G11/$H$7/12 -> 2564.5194 | J11: =+$G11/$H$7/12 -> 2564.5194 | K11: =+$G11/$H$7/12 -> 2564.5194 | L11: =+$G11/$H$7/12 -> 2564.5194 | M11: =+$G11/$H$7/12 -> 2564.5194 | N11: =+$G11/$H$7/12 -> 2564.5194 | O11: =+$G11/$H$7/12 -> 2564.5194 | P11: =+$G11/$H$7/12 -> 2564.5194 | ... T11: =+$G11/$H$7/12 -> 2564.5194 | U11: =SUM(I11:T11) -> 30774.233 | V11: =U11+'FAR19'!V11 -> 61548.467 | W11: =+G11-V11 -> 30774.233
D13: =SUM(D6:D12) -> 171130.1 | E13: =SUM(E6:E12) -> 0 | G13: =SUM(G8:G12) -> 171130.1 | I13: =SUM(I8:I12) -> 4753.6139 | J13: =SUM(J8:J12) -> 4753.6139 | K13: =SUM(K8:K12) -> 4753.6139 | L13: =SUM(L8:L12) -> 4753.6139 | M13: =SUM(M8:M12) -> 4753.6139 | N13: =SUM(N8:N12) -> 4753.6139 | O13: =SUM(O8:O12) -> 4753.6139 | P13: =SUM(P8:P12) -> 4753.6139 | ... W13: =SUM(W8:W12) -> 43557.639
A15: Date | B15: Reference | C15: Description | D15: Cost | E15: Additions | F15: Disp | G15: Total | H15: Per | I15: 43555 | J15: 43585 | K15: 43616 | L15: 43646 | M15: 43677 | N15: 43708 | O15: 43738 | P15: 43769 | Q15: 43799 | R15: 43830 | S15: 43861 | T15: 43890 | U15: Depn for Year | V15: Accum Depn | W15: NBV 2020
A16: 6200>020 (Furniture & Fittings>Cost) | H16: 6 | I16: =+A16 -> 6200>020 (Furniture & Fittings>Cost)
A18: 42836 | B18: 30110 | C18: BFS - 15 X Roberto High Back Chairs | D18: ='FAR19'!G18 -> 52250 | G18: =+D18+E18-F18 -> 52250 | I18: =+$G18/$H$16/12 -> 725.69444 | J18: =+$G18/$H$16/12 -> 725.69444 | K18: =+$G18/$H$16/12 -> 725.69444 | L18: =+$G18/$H$16/12 -> 725.69444 | M18: =+$G18/$H$16/12 -> 725.69444 | N18: =+$G18/$H$16/12 -> 725.69444 | O18: =+$G18/$H$16/12 -> 725.69444 | P18: =+$G18/$H$16/12 -> 725.69444 | ... T18: =+$G18/$H$16/12 -> 725.69444 | U18: =SUM(I18:T18) -> 8708.3333 | V18: =U18+'FAR19'!V18 -> 25126.922 | W18: =+G18-V18 -> 27123.078
A19: 43165 | B19: Piyox-TV | C19: Boardroom TV - Samsung 75" UHD | D19: ='FAR19'!G19 -> 44144 | G19: =+D19+E19-F19 -> 44144 | I19: =+$G19/$H$16/12 -> 613.11111 | J19: =+$G19/$H$16/12 -> 613.11111 | K19: =+$G19/$H$16/12 -> 613.11111 | L19: =+$G19/$H$16/12 -> 613.11111 | M19: =+$G19/$H$16/12 -> 613.11111 | N19: =+$G19/$H$16/12 -> 613.11111 | O19: =+$G19/$H$16/12 -> 613.11111 | P19: =+$G19/$H$16/12 -> 613.11111 | ... T19: =+$G19/$H$16/12 -> 613.11111 | U19: =SUM(I19:T19) -> 7357.3333 | V19: =U19+'FAR19'!V19 -> 14605.483 | W19: =+G19-V19 -> 29538.518
A20: 43179 | B20: 32006 | C20: BFS - 5 X Roberto High Back Chairs | D20: ='FAR19'!G20 -> 19430 | G20: =+D20+E20-F20 -> 19430 | I20: =+$G20/$H$16/12 -> 269.86111 | J20: =+$G20/$H$16/12 -> 269.86111 | K20: =+$G20/$H$16/12 -> 269.86111 | L20: =+$G20/$H$16/12 -> 269.86111 | M20: =+$G20/$H$16/12 -> 269.86111 | N20: =+$G20/$H$16/12 -> 269.86111 | O20: =+$G20/$H$16/12 -> 269.86111 | P20: =+$G20/$H$16/12 -> 269.86111 | ... T20: =+$G20/$H$16/12 -> 269.86111 | U20: =SUM(I20:T20) -> 3238.3333 | V20: =U20+'FAR19'!V20 -> 6304.3992 | W20: =+G20-V20 -> 13125.601
A21: 43578 | B21: INV00651 | C21: C & D Design - Boardroom Table | E21: 26544 | G21: =+D21+E21-F21 -> 26544 | J21: =+$G21/$H$16/365*(30-23) -> 84.843836 | K21: =+$G21/$H$16/12 -> 368.66667 | L21: =+$G21/$H$16/12 -> 368.66667 | M21: =+$G21/$H$16/12 -> 368.66667 | N21: =+$G21/$H$16/12 -> 368.66667 | O21: =+$G21/$H$16/12 -> 368.66667 | P21: =+$G21/$H$16/12 -> 368.66667 | Q21: =+$G21/$H$16/12 -> 368.66667 | R21: =+$G21/$H$16/12 -> 368.66667 | ... T21: =+$G21/$H$16/12 -> 368.66667 | U21: =SUM(I21:T21) -> 3771.5105 | V21: =U21+'FAR19'!V21 -> 3771.5105 | W21: =+G21-V21 -> 22772.489
A22: 43710 | B22: 34825 | C22: BFS - 4 X Roberto High Back Chairs | E22: =15064+703 -> 15767 | G22: =+D22+E22-F22 -> 15767 | O22: =+$G22/$H$16/12 -> 218.98611 | P22: =+$G22/$H$16/12 -> 218.98611 | Q22: =+$G22/$H$16/12 -> 218.98611 | R22: =+$G22/$H$16/12 -> 218.98611 | S22: =+$G22/$H$16/12 -> 218.98611 | T22: =+$G22/$H$16/12 -> 218.98611 | U22: =SUM(I22:T22) -> 1313.9167 | V22: =U22 -> 1313.9167 | W22: =+G22-V22 -> 14453.083
A23: 43710 | B23: 34825 | C23: BFS - 10 X Pasquale Visitors Arm Chairs | E23: =24500+1147 -> 25647 | G23: =+D23+E23-F23 -> 25647 | O23: =+$G23/$H$16/12 -> 356.20833 | P23: =+$G23/$H$16/12 -> 356.20833 | Q23: =+$G23/$H$16/12 -> 356.20833 | R23: =+$G23/$H$16/12 -> 356.20833 | S23: =+$G23/$H$16/12 -> 356.20833 | T23: =+$G23/$H$16/12 -> 356.20833 | U23: =SUM(I23:T23) -> 2137.25 | V23: =U23 -> 2137.25 | W23: =+G23-V23 -> 23509.75
D25: =SUM(D16:D24) -> 115824 | E25: =SUM(E16:E24) -> 67958 | F25: =SUM(F16:F23) -> 0 | G25: =SUM(D25:F25) -> 183782 | I25: =SUM(I18:I24) -> 1608.6667 | J25: =SUM(J18:J24) -> 1693.5105 | K25: =SUM(K18:K24) -> 1977.3333 | L25: =SUM(L18:L24) -> 1977.3333 | M25: =SUM(M18:M24) -> 1977.3333 | N25: =SUM(N18:N24) -> 1977.3333 | O25: =SUM(O18:O24) -> 2552.5278 | P25: =SUM(P18:P24) -> 2552.5278 | ... W25: =SUM(W18:W24) -> 130522.52
A27: Date | B27: Reference | C27: Description | D27: Cost | E27: Additions | F27: Disp | G27: Total | H27: Per | I27: 43555 | J27: 43585 | K27: 43616 | L27: 43646 | M27: 43677 | N27: 43708 | O27: 43738 | P27: 43769 | Q27: 43799 | R27: 43830 | S27: 43861 | T27: 43890 | U27: Depn for Year | V27: Accum Depn | W27: NBV 2020
A28: 6300>020 (Motor Vehicles>Cost) | H28: 5 | I28: =+A28 -> 6300>020 (Motor Vehicles>Cost)
A30: 42860 | B30: 89009640 | C30: Rivonia Toyota: Corolla Quest 1.6 AT | D30: 255969.92 | G30: =+D30+E30-F30 -> 255969.92 | I30: =+$G30/$H$28/12 -> 4266.1653 | J30: =+$G30/$H$28/12 -> 4266.1653 | K30: =+$G30/$H$28/12 -> 4266.1653 | L30: =+$G30/$H$28/12 -> 4266.1653 | M30: =+$G30/$H$28/12 -> 4266.1653 | N30: =+$G30/$H$28/12 -> 4266.1653 | O30: =+$G30/$H$28/12 -> 4266.1653 | P30: =+$G30/$H$28/12 -> 4266.1653 | ... T30: =+$G30/$H$28/12 -> 4266.1653 | U30: =SUM(I30:T30) -> 51193.984 | V30: =U30+'FAR19'!V27 -> 144430.15 | W30: =+G30-V30 -> 111539.77
D32: =SUM(D30) -> 255969.92 | E32: =SUM(E30) -> 0 | F32: =SUM(F30) -> 0 | G32: =SUM(D32:F32) -> 255969.92 | I32: =SUM(I30) -> 4266.1653 | J32: =SUM(J30) -> 4266.1653 | K32: =SUM(K30) -> 4266.1653 | L32: =SUM(L30) -> 4266.1653 | M32: =SUM(M30) -> 4266.1653 | N32: =SUM(N30) -> 4266.1653 | O32: =SUM(O30) -> 4266.1653 | P32: =SUM(P30) -> 4266.1653 | ... W32: =SUM(W30) -> 111539.77
A34: Grand Total | D34: =D13+D25+D32 -> 542924.02 | E34: =E13+E25+E32 -> 67958 | F34: =F13+F25+F32 -> 0 | G34: =G13+G25+G32 -> 610882.02 | I34: =I13+I25+I32 -> 10628.446 | J34: =J13+J25+J32 -> 10713.29 | K34: =K13+K25+K32 -> 10997.113 | L34: =L13+L25+L32 -> 10997.113 | M34: =M13+M25+M32 -> 10997.113 | N34: =N13+N25+N32 -> 10997.113 | O34: =O13+O25+O32 -> 11572.307 | P34: =P13+P25+P32 -> 11572.307 | ... W34: =W13+W25+W32 -> 285619.93
U36: ='FAR19'!W31-'FAR20'!W34 -> 66806.028 | V36: NBV 2020 less NBV 2019
U37: =U34 -> 134764.03 | V37: Depr for a year
U38: =-E34 -> -67958 | V38: Additional assets
U39: =SUM(U37:U38) -> 66806.028

Sheet FAR21
A1: FAR MRC Management Services
A3: Ledger Accounts: MARCH 2020 - FEBRUARY 2021
A4: Date | B4: Reference | C4: Description | D4: Cost (ExVAT) | E4: Additions | F4: Disp | G4: Total | H4: Per | I4: 43921 | J4: 43951 | K4: 43982 | L4: 44012 | M4: 44043 | N4: 44074 | O4: 44104 | P4: 44135 | Q4: 44165 | R4: 44196 | S4: 44227 | T4: 44255 | U4: Depn for Year | V4: Accum Depn | W4: NBV 2021
A6: 6100>020 (Computer Equipment>Cost) | I6: =+A6 -> 6100>020 (Computer Equipment>Cost)
H7: 3
A8: 42825 | B8: 18431 | C8: SevenC - 2 X HP Desktop CPU (AP & EM) | D8: ='FAR20'!D8 -> 16077.6 | G8: =+D8+E8-F8 -> 16077.6 | I8: =+$G8/$H$7/12 -> 446.6 | U8: =SUM(I8:T8) -> 446.6 | V8: ='FAR20'!V8+U8 -> 16077.6 | W8: =+G8-V8 -> 0
A9: 42825 | B9: 18431 | C9: SevenC - HP ProBook 450 G4 Laptop (JN) | D9: ='FAR20'!D9 -> 10078.8 | G9: =+D9+E9-F9 -> 10078.8 | I9: =+$G9/$H$7/12 -> 279.96667 | U9: =SUM(I9:T9) -> 279.96667 | V9: ='FAR20'!V9+U9 -> 10078.8 | W9: =+G9-V9 -> 0
A10: 43046 | B10: INA90085 | C10: Heart FM - CBA/Polycom System / VC | D10: ='FAR20'!D10 -> 52651 | G10: =+D10+E10-F10 -> 52651 | I10: =+$G10/$H$7/12 -> 1462.5278 | J10: =+$G10/$H$7/12 -> 1462.5278 | K10: =+$G10/$H$7/12 -> 1462.5278 | L10: =+$G10/$H$7/12 -> 1462.5278 | M10: =+$G10/$H$7/12 -> 1462.5278 | N10: =+$G10/$H$7/12 -> 1462.5278 | O10: =+$G10/$H$7/12 -> 1462.5278 | P10: =+$G10/$H$7/12 -> 1462.5278 | Q10: 356.62 | U10: =SUM(I10:T10) -> 12056.842 | V10: ='FAR20'!V10+U10 -> 52651.004 | W10: =+G10-V10 -> -0.0036377473
A11: 43160 | B11: 21643 | C11: SevenC - 6 X HP Desktop & Keyboards | D11: ='FAR20'!D11 -> 92322.7 | G11: =+D11+E11-F11 -> 92322.7 | I11: =+$G11/$H$7/12 -> 2564.5194 | J11: =+$G11/$H$7/12 -> 2564.5194 | K11: =+$G11/$H$7/12 -> 2564.5194 | L11: =+$G11/$H$7/12 -> 2564.5194 | M11: =+$G11/$H$7/12 -> 2564.5194 | N11: =+$G11/$H$7/12 -> 2564.5194 | O11: =+$G11/$H$7/12 -> 2564.5194 | P11: =+$G11/$H$7/12 -> 2564.5194 | ... T11: =+$G11/$H$7/12 -> 2564.5194 | U11: =SUM(I11:T11) -> 30774.233 | V11: ='FAR20'!V11+U11 -> 92322.7 | W11: =+G11-V11 -> 0
A12: 44509 | B12: INV33588 | C12: SevenC - Server: Dell PowerEdge R440 | E12: 92565.27 | G12: =+D12+E12-F12 -> 92565.27 | I12: 0 | J12: 0 | K12: 0 | L12: 0 | M12: 0 | N12: 0 | O12: 0 | P12: 0 | Q12: 0 | R12: 0 | S12: 0 | T12: 0 | U12: =SUM(I12:T12) -> 0 | V12: ='FAR20'!V12+U12 -> 0 | W12: =+G12-V12 -> 92565.27
A13: (Brought to use in March 21)
D14: =SUM(D6:D13) -> 171130.1 | E14: =SUM(E6:E13) -> 92565.27 | G14: =SUM(G8:G13) -> 263695.37 | I14: =SUM(I8:I13) -> 4753.6139 | J14: =SUM(J8:J13) -> 4027.0472 | K14: =SUM(K8:K13) -> 4027.0472 | L14: =SUM(L8:L13) -> 4027.0472 | M14: =SUM(M8:M13) -> 4027.0472 | N14: =SUM(N8:N13) -> 4027.0472 | O14: =SUM(O8:O13) -> 4027.0472 | P14: =SUM(P8:P13) -> 4027.0472 | ... W14: =SUM(W8:W13) -> 92565.266
A16: Date | B16: Reference | C16: Description | D16: Cost | E16: Additions | F16: Disp | G16: Total | H16: Per | I16: 43921 | J16: 43951 | K16: 43982 | L16: 44012 | M16: 44043 | N16: 44074 | O16: 44104 | P16: 44135 | Q16: 44165 | R16: 44196 | S16: 44227 | T16: 44255 | U16: Depn for Year | V16: Accum Depn | W16: NBV 2021
A17: 6200>020 (Furniture & Fittings>Cost) | H17: 6 | I17: =+A17 -> 6200>020 (Furniture & Fittings>Cost)
A19: 42836 | B19: 30110 | C19: BFS - 15 X Roberto High Back Chairs | D19: ='FAR20'!G18 -> 52250 | G19: =+D19+E19-F19 -> 52250 | I19: =+$G19/$H$17/12 -> 725.69444 | J19: =+$G19/$H$17/12 -> 725.69444 | K19: =+$G19/$H$17/12 -> 725.69444 | L19: =+$G19/$H$17/12 -> 725.69444 | M19: =+$G19/$H$17/12 -> 725.69444 | N19: =+$G19/$H$17/12 -> 725.69444 | O19: =+$G19/$H$17/12 -> 725.69444 | P19: =+$G19/$H$17/12 -> 725.69444 | ... T19: =+$G19/$H$17/12 -> 725.69444 | U19: =SUM(I19:T19) -> 8708.3333 | V19: ='FAR20'!V18+U19 -> 33835.255 | W19: =+G19-V19 -> 18414.745
A20: 43165 | B20: Piyox-TV | C20: Boardroom TV - Samsung 75" UHD | D20: ='FAR20'!G19 -> 44144 | G20: =+D20+E20-F20 -> 44144 | I20: =+$G20/$H$17/12 -> 613.11111 | J20: =+$G20/$H$17/12 -> 613.11111 | K20: =+$G20/$H$17/12 -> 613.11111 | L20: =+$G20/$H$17/12 -> 613.11111 | M20: =+$G20/$H$17/12 -> 613.11111 | N20: =+$G20/$H$17/12 -> 613.11111 | O20: =+$G20/$H$17/12 -> 613.11111 | P20: =+$G20/$H$17/12 -> 613.11111 | ... T20: =+$G20/$H$17/12 -> 613.11111 | U20: =SUM(I20:T20) -> 7357.3333 | V20: ='FAR20'!V19+U20 -> 21962.816 | W20: =+G20-V20 -> 22181.184
A21: 43179 | B21: 32006 | C21: BFS - 5 X Roberto High Back Chairs | D21: ='FAR20'!G20 -> 19430 | G21: =+D21+E21-F21 -> 19430 | I21: =+$G21/$H$17/12 -> 269.86111 | J21: =+$G21/$H$17/12 -> 269.86111 | K21: =+$G21/$H$17/12 -> 269.86111 | L21: =+$G21/$H$17/12 -> 269.86111 | M21: =+$G21/$H$17/12 -> 269.86111 | N21: =+$G21/$H$17/12 -> 269.86111 | O21: =+$G21/$H$17/12 -> 269.86111 | P21: =+$G21/$H$17/12 -> 269.86111 | ... T21: =+$G21/$H$17/12 -> 269.86111 | U21: =SUM(I21:T21) -> 3238.3333 | V21: ='FAR20'!V20+U21 -> 9542.7325 | W21: =+G21-V21 -> 9887.2675
A22: 43578 | B22: INV00651 | C22: C & D Design - Boardroom Table | D22: ='FAR20'!G21 -> 26544 | G22: =+D22+E22-F22 -> 26544 | I22: =+$G22/$H$17/12 -> 368.66667 | J22: =+$G22/$H$17/12 -> 368.66667 | K22: =+$G22/$H$17/12 -> 368.66667 | L22: =+$G22/$H$17/12 -> 368.66667 | M22: =+$G22/$H$17/12 -> 368.66667 | N22: =+$G22/$H$17/12 -> 368.66667 | O22: =+$G22/$H$17/12 -> 368.66667 | P22: =+$G22/$H$17/12 -> 368.66667 | ... T22: =+$G22/$H$17/12 -> 368.66667 | U22: =SUM(I22:T22) -> 4424 | V22: ='FAR20'!V21+U22 -> 8195.5105 | W22: =+G22-V22 -> 18348.489
A23: 43710 | B23: 34825 | C23: BFS - 4 X Roberto High Back Chairs | D23: ='FAR20'!G22 -> 15767 | G23: =+D23+E23-F23 -> 15767 | I23: =+$G23/$H$17/12 -> 218.98611 | J23: =+$G23/$H$17/12 -> 218.98611 | K23: =+$G23/$H$17/12 -> 218.98611 | L23: =+$G23/$H$17/12 -> 218.98611 | M23: =+$G23/$H$17/12 -> 218.98611 | N23: =+$G23/$H$17/12 -> 218.98611 | O23: =+$G23/$H$17/12 -> 218.98611 | P23: =+$G23/$H$17/12 -> 218.98611 | ... T23: =+$G23/$H$17/12 -> 218.98611 | U23: =SUM(I23:T23) -> 2627.8333 | V23: ='FAR20'!V22+U23 -> 3941.75 | W23: =+G23-V23 -> 11825.25
A24: 43710 | B24: 34825 | C24: BFS - 10 X Pasquale Visitors Arm Chairs | D24: ='FAR20'!G23 -> 25647 | G24: =+D24+E24-F24 -> 25647 | I24: =+$G24/$H$17/12 -> 356.20833 | J24: =+$G24/$H$17/12 -> 356.20833 | K24: =+$G24/$H$17/12 -> 356.20833 | L24: =+$G24/$H$17/12 -> 356.20833 | M24: =+$G24/$H$17/12 -> 356.20833 | N24: =+$G24/$H$17/12 -> 356.20833 | O24: =+$G24/$H$17/12 -> 356.20833 | P24: =+$G24/$H$17/12 -> 356.20833 | ... T24: =+$G24/$H$17/12 -> 356.20833 | U24: =SUM(I24:T24) -> 4274.5 | V24: ='FAR20'!V23+U24 -> 6411.75 | W24: =+G24-V24 -> 19235.25
D26: =SUM(D17:D25) -> 183782 | E26: =SUM(E17:E25) -> 0 | F26: =SUM(F17:F24) -> 0 | G26: =SUM(D26:F26) -> 183782 | I26: =SUM(I19:I25) -> 2552.5278 | J26: =SUM(J19:J25) -> 2552.5278 | K26: =SUM(K19:K25) -> 2552.5278 | L26: =SUM(L19:L25) -> 2552.5278 | M26: =SUM(M19:M25) -> 2552.5278 | N26: =SUM(N19:N25) -> 2552.5278 | O26: =SUM(O19:O25) -> 2552.5278 | P26: =SUM(P19:P25) -> 2552.5278 | ... W26: =SUM(W19:W25) -> 99892.186
A28: Date | B28: Reference | C28: Description | D28: Cost | E28: Additions | F28: Disp | G28: Total | H28: Per | I28: 43921 | J28: 43951 | K28: 43982 | L28: 44012 | M28: 44043 | N28: 44074 | O28: 44104 | P28: 44135 | Q28: 44165 | R28: 44196 | S28: 44227 | T28: 44255 | U28: Depn for Year | V28: Accum Depn | W28: NBV 2021
A29: 6300>020 (Motor Vehicles>Cost) | H29: 5 | I29: =+A29 -> 6300>020 (Motor Vehicles>Cost)
A31: 42860 | B31: 89009640 | C31: Rivonia Toyota: Corolla Quest 1.6 AT | D31: 255969.92 | G31: =+D31+E31-F31 -> 255969.92 | I31: =+$G31/$H$29/12 -> 4266.1653 | J31: =+$G31/$H$29/12 -> 4266.1653 | K31: =+$G31/$H$29/12 -> 4266.1653 | L31: =+$G31/$H$29/12 -> 4266.1653 | M31: =+$G31/$H$29/12 -> 4266.1653 | N31: =+$G31/$H$29/12 -> 4266.1653 | O31: =+$G31/$H$29/12 -> 4266.1653 | P31: =+$G31/$H$29/12 -> 4266.1653 | ... T31: =+$G31/$H$29/12 -> 4266.1653 | U31: =SUM(I31:T31) -> 51193.984 | V31: =U31+'FAR20'!V30 -> 195624.13 | W31: =+G31-V31 -> 60345.785
D33: =SUM(D31) -> 255969.92 | E33: =SUM(E31) -> 0 | F33: =SUM(F31) -> 0 | G33: =SUM(D33:F33) -> 255969.92 | I33: =SUM(I31) -> 4266.1653 | J33: =SUM(J31) -> 4266.1653 | K33: =SUM(K31) -> 4266.1653 | L33: =SUM(L31) -> 4266.1653 | M33: =SUM(M31) -> 4266.1653 | N33: =SUM(N31) -> 4266.1653 | O33: =SUM(O31) -> 4266.1653 | P33: =SUM(P31) -> 4266.1653 | ... W33: =SUM(W31) -> 60345.785
A35: Grand Total | D35: =D14+D26+D33 -> 610882.02 | E35: =E14+E26+E33 -> 92565.27 | F35: =F14+F26+F33 -> 0 | G35: =G14+G26+G33 -> 703447.29 | I35: =I14+I26+I33 -> 11572.307 | J35: =J14+J26+J33 -> 10845.74 | K35: =K14+K26+K33 -> 10845.74 | L35: =L14+L26+L33 -> 10845.74 | M35: =M14+M26+M33 -> 10845.74 | N35: =N14+N26+N33 -> 10845.74 | O35: =O14+O26+O33 -> 10845.74 | P35: =P14+P26+P33 -> 10845.74 | ... W35: =W14+W26+W33 -> 252803.24

Sheet FAR22
A1: FAR MRC Management Services
A3: Ledger Accounts: MARCH 2021 - FEBRUARY 2022
A4: Date | B4: Reference | C4: Description | D4: Cost (ExVAT) | E4: Additions | F4: Disp | G4: Total | H4: Per | I4: 44286 | J4: 44316 | K4: 44347 | L4: 44377 | M4: 44408 | N4: 44439 | O4: 44469 | P4: 44500 | Q4: 44530 | R4: 44561 | S4: 44592 | T4: 44620 | U4: Depn for Year | V4: Accum Depn | W4: NBV 2022
A6: 6100>020 (Computer Equipment>Cost) | I6: =+A6 -> 6100>020 (Computer Equipment>Cost)
H7: 3
A8: 42825 | B8: 18431 | C8: SevenC - 2 X HP Desktop CPU (AP & EM) | D8: ='FAR21'!G8 -> 16077.6 | G8: =+D8+E8-F8 -> 16077.6 | I8: 0 | J8: 0 | K8: 0 | L8: 0 | M8: 0 | N8: 0 | O8: 0 | P8: 0 | Q8: 0 | R8: 0 | S8: 0 | T8: 0 | U8: =SUM(I8:T8) -> 0 | V8: ='FAR21'!V8+U8 -> 16077.6 | W8: =+G8-V8 -> 0
A9: 42825 | B9: 18431 | C9: SevenC - HP ProBook 450 G4 Laptop (JN) | D9: ='FAR21'!G9 -> 10078.8 | G9: =+D9+E9-F9 -> 10078.8 | I9: 0 | J9: 0 | K9: 0 | L9: 0 | M9: 0 | N9: 0 | O9: 0 | P9: 0 | Q9: 0 | R9: 0 | S9: 0 | T9: 0 | U9: =SUM(I9:T9) -> 0 | V9: ='FAR21'!V9+U9 -> 10078.8 | W9: =+G9-V9 -> 0
A10: 43046 | B10: INA90085 | C10: Heart FM - CBA/Polycom System / VC | D10: ='FAR21'!G10 -> 52651 | G10: =+D10+E10-F10 -> 52651 | I10: 0 | J10: 0 | K10: 0 | L10: 0 | M10: 0 | N10: 0 | O10: 0 | P10: 0 | Q10: 0 | R10: 0 | S10: 0 | T10: 0 | U10: =SUM(I10:T10) -> 0 | V10: ='FAR21'!V10+U10 -> 52651.004 | W10: =+G10-V10 -> -0.0036377473
A11: 43160 | B11: 21643 | C11: SevenC - 6 X HP Desktop & Keyboards | D11: ='FAR21'!G11 -> 92322.7 | G11: =+D11+E11-F11 -> 92322.7 | I11: 0 | J11: 0 | K11: 0 | L11: 0 | M11: 0 | N11: 0 | O11: 0 | P11: 0 | Q11: 0 | R11: 0 | S11: 0 | T11: 0 | U11: =SUM(I11:T11) -> 0 | V11: ='FAR21'!V11+U11 -> 92322.7 | W11: =+G11-V11 -> 0
A12: 44144 | B12: INV33588 | C12: SevenC - Server: Dell PowerEdge R440 | D12: ='FAR21'!G12 -> 92565.27 | G12: =+D12+E12-F12 -> 92565.27 | I12: =+$G12/$H$7/12 -> 2571.2575 | J12: =+$G12/$H$7/12 -> 2571.2575 | K12: =+$G12/$H$7/12 -> 2571.2575 | L12: =+$G12/$H$7/12 -> 2571.2575 | M12: =+$G12/$H$7/12 -> 2571.2575 | N12: =+$G12/$H$7/12 -> 2571.2575 | O12: =+$G12/$H$7/12 -> 2571.2575 | P12: =+$G12/$H$7/12 -> 2571.2575 | ... T12: =+$G12/$H$7/12 -> 2571.2575 | U12: =SUM(I12:T12) -> 30855.09 | V12: ='FAR21'!V12+U12 -> 30855.09 | W12: =+G12-V12 -> 61710.18
A13: (Brought to used in March 21)
D14: =SUM(D6:D13) -> 263695.37 | E14: =SUM(E6:E13) -> 0 | G14: =SUM(G8:G13) -> 263695.37 | I14: =SUM(I8:I13) -> 2571.2575 | J14: =SUM(J8:J13) -> 2571.2575 | K14: =SUM(K8:K13) -> 2571.2575 | L14: =SUM(L8:L13) -> 2571.2575 | M14: =SUM(M8:M13) -> 2571.2575 | N14: =SUM(N8:N13) -> 2571.2575 | O14: =SUM(O8:O13) -> 2571.2575 | P14: =SUM(P8:P13) -> 2571.2575 | ... W14: =SUM(W8:W13) -> 61710.176
A16: Date | B16: Reference | C16: Description | D16: Cost | E16: Additions | F16: Disp | G16: Total | H16: Per | I16: 44286 | J16: 44316 | K16: 44347 | L16: 44377 | M16: 44408 | N16: 44439 | O16: 44469 | P16: 44500 | Q16: 44530 | R16: 44561 | S16: 44592 | T16: 44255 | U16: Depn for Year | V16: Accum Depn | W16: NBV 2022
A17: 6200>020 (Furniture & Fittings>Cost) | H17: 6 | I17: =+A17 -> 6200>020 (Furniture & Fittings>Cost)
A19: 42836 | B19: 30110 | C19: BFS - 15 X Roberto High Back Chairs | D19: ='FAR21'!G19 -> 52250 | G19: =+D19+E19-F19 -> 52250 | I19: =+$G19/$H$17/12 -> 725.69444 | J19: =+$G19/$H$17/12 -> 725.69444 | K19: =+$G19/$H$17/12 -> 725.69444 | L19: =+$G19/$H$17/12 -> 725.69444 | M19: =+$G19/$H$17/12 -> 725.69444 | N19: =+$G19/$H$17/12 -> 725.69444 | O19: =+$G19/$H$17/12 -> 725.69444 | P19: =+$G19/$H$17/12 -> 725.69444 | ... T19: =+$G19/$H$17/12 -> 725.69444 | U19: =SUM(I19:T19) -> 8708.3333 | V19: ='FAR21'!V19+U19 -> 42543.588 | W19: =+G19-V19 -> 9706.4117
A20: 43165 | B20: Piyox-TV | C20: Boardroom TV - Samsung 75" UHD | D20: ='FAR21'!G20 -> 44144 | G20: =+D20+E20-F20 -> 44144 | I20: =+$G20/$H$17/12 -> 613.11111 | J20: =+$G20/$H$17/12 -> 613.11111 | K20: =+$G20/$H$17/12 -> 613.11111 | L20: =+$G20/$H$17/12 -> 613.11111 | M20: =+$G20/$H$17/12 -> 613.11111 | N20: =+$G20/$H$17/12 -> 613.11111 | O20: =+$G20/$H$17/12 -> 613.11111 | P20: =+$G20/$H$17/12 -> 613.11111 | ... T20: =+$G20/$H$17/12 -> 613.11111 | U20: =SUM(I20:T20) -> 7357.3333 | V20: ='FAR21'!V20+U20 -> 29320.149 | W20: =+G20-V20 -> 14823.851
A21: 43179 | B21: 32006 | C21: BFS - 5 X Roberto High Back Chairs | D21: ='FAR21'!G21 -> 19430 | G21: =+D21+E21-F21 -> 19430 | I21: =+$G21/$H$17/12 -> 269.86111 | J21: =+$G21/$H$17/12 -> 269.86111 | K21: =+$G21/$H$17/12 -> 269.86111 | L21: =+$G21/$H$17/12 -> 269.86111 | M21: =+$G21/$H$17/12 -> 269.86111 | N21: =+$G21/$H$17/12 -> 269.86111 | O21: =+$G21/$H$17/12 -> 269.86111 | P21: =+$G21/$H$17/12 -> 269.86111 | ... T21: =+$G21/$H$17/12 -> 269.86111 | U21: =SUM(I21:T21) -> 3238.3333 | V21: ='FAR21'!V21+U21 -> 12781.066 | W21: =+G21-V21 -> 6648.9342
A22: 43578 | B22: INV00651 | C22: C & D Design - Boardroom Table | D22: ='FAR21'!G22 -> 26544 | G22: =+D22+E22-F22 -> 26544 | I22: =+$G22/$H$17/12 -> 368.66667 | J22: =+$G22/$H$17/12 -> 368.66667 | K22: =+$G22/$H$17/12 -> 368.66667 | L22: =+$G22/$H$17/12 -> 368.66667 | M22: =+$G22/$H$17/12 -> 368.66667 | N22: =+$G22/$H$17/12 -> 368.66667 | O22: =+$G22/$H$17/12 -> 368.66667 | P22: =+$G22/$H$17/12 -> 368.66667 | ... T22: =+$G22/$H$17/12 -> 368.66667 | U22: =SUM(I22:T22) -> 4424 | V22: ='FAR21'!V22+U22 -> 12619.511 | W22: =+G22-V22 -> 13924.489
A23: 43710 | B23: 34825 | C23: BFS - 4 X Roberto High Back Chairs | D23: ='FAR21'!G23 -> 15767 | G23: =+D23+E23-F23 -> 15767 | I23: =+$G23/$H$17/12 -> 218.98611 | J23: =+$G23/$H$17/12 -> 218.98611 | K23: =+$G23/$H$17/12 -> 218.98611 | L23: =+$G23/$H$17/12 -> 218.98611 | M23: =+$G23/$H$17/12 -> 218.98611 | N23: =+$G23/$H$17/12 -> 218.98611 | O23: =+$G23/$H$17/12 -> 218.98611 | P23: =+$G23/$H$17/12 -> 218.98611 | ... T23: =+$G23/$H$17/12 -> 218.98611 | U23: =SUM(I23:T23) -> 2627.8333 | V23: ='FAR21'!V23+U23 -> 6569.5833 | W23: =+G23-V23 -> 9197.4167
A24: 43710 | B24: 34825 | C24: BFS - 10 X Pasquale Visitors Arm Chairs | D24: ='FAR21'!G24 -> 25647 | G24: =+D24+E24-F24 -> 25647 | I24: =+$G24/$H$17/12 -> 356.20833 | J24: =+$G24/$H$17/12 -> 356.20833 | K24: =+$G24/$H$17/12 -> 356.20833 | L24: =+$G24/$H$17/12 -> 356.20833 | M24: =+$G24/$H$17/12 -> 356.20833 | N24: =+$G24/$H$17/12 -> 356.20833 | O24: =+$G24/$H$17/12 -> 356.20833 | P24: =+$G24/$H$17/12 -> 356.20833 | ... T24: =+$G24/$H$17/12 -> 356.20833 | U24: =SUM(I24:T24) -> 4274.5 | V24: ='FAR21'!V24+U24 -> 10686.25 | W24: =+G24-V24 -> 14960.75
D26: =SUM(D17:D25) -> 183782 | E26: =SUM(E17:E25) -> 0 | F26: =SUM(F17:F24) -> 0 | G26: =SUM(D26:F26) -> 183782 | I26: =SUM(I19:I25) -> 2552.5278 | J26: =SUM(J19:J25) -> 2552.5278 | K26: =SUM(K19:K25) -> 2552.5278 | L26: =SUM(L19:L25) -> 2552.5278 | M26: =SUM(M19:M25) -> 2552.5278 | N26: =SUM(N19:N25) -> 2552.5278 | O26: =SUM(O19:O25) -> 2552.5278 | P26: =SUM(P19:P25) -> 2552.5278 | ... W26: =SUM(W19:W25) -> 69261.853
A28: Date | B28: Reference | C28: Description | D28: Cost | E28: Additions | F28: Disp | G28: Total | H28: Per | I28: 44286 | J28: 44316 | K28: 44347 | L28: 44377 | M28: 44408 | N28: 44439 | O28: 44469 | P28: 44500 | Q28: 44530 | R28: 44561 | S28: 44592 | T28: 44620 | U28: Depn for Year | V28: Accum Depn | W28: NBV 2022
A29: 6300>020 (Motor Vehicles>Cost) | H29: 5 | I29: =+A29 -> 6300>020 (Motor Vehicles>Cost)
A31: 42860 | B31: 89009640 | C31: Rivonia Toyota: Corolla Quest 1.6 AT | D31: ='FAR21'!G31 -> 255969.92 | G31: =+D31+E31-F31 -> 255969.92 | I31: =+$G31/$H$29/12 -> 4266.1653 | J31: =+$G31/$H$29/12 -> 4266.1653 | K31: =+$G31/$H$29/12 -> 4266.1653 | L31: =+$G31/$H$29/12 -> 4266.1653 | M31: =+$G31/$H$29/12 -> 4266.1653 | N31: =+$G31/$H$29/12 -> 4266.1653 | O31: =+$G31/$H$29/12 -> 4266.1653 | P31: =+$G31/$H$29/12 -> 4266.1653 | ... T31: =+$G31/$H$29/12 -> 4266.1653 | U31: =SUM(I31:T31) -> 51193.984 | V31: =U31+'FAR21'!V31 -> 246818.12 | W31: =+G31-V31 -> 9151.8012
D33: =SUM(D31) -> 255969.92 | E33: =SUM(E31) -> 0 | F33: =SUM(F31) -> 0 | G33: =SUM(D33:F33) -> 255969.92 | I33: =SUM(I31) -> 4266.1653 | J33: =SUM(J31) -> 4266.1653 | K33: =SUM(K31) -> 4266.1653 | L33: =SUM(L31) -> 4266.1653 | M33: =SUM(M31) -> 4266.1653 | N33: =SUM(N31) -> 4266.1653 | O33: =SUM(O31) -> 4266.1653 | P33: =SUM(P31) -> 4266.1653 | ... W33: =SUM(W31) -> 9151.8012
A35: Grand Total | D35: =D14+D26+D33 -> 703447.29 | E35: =E14+E26+E33 -> 0 | F35: =F14+F26+F33 -> 0 | G35: =G14+G26+G33 -> 703447.29 | I35: =I14+I26+I33 -> 9389.9506 | J35: =J14+J26+J33 -> 9389.9506 | K35: =K14+K26+K33 -> 9389.9506 | L35: =L14+L26+L33 -> 9389.9506 | M35: =M14+M26+M33 -> 9389.9506 | N35: =N14+N26+N33 -> 9389.9506 | O35: =O14+O26+O33 -> 9389.9506 | P35: =P14+P26+P33 -> 9389.9506 | ... W35: =W14+W26+W33 -> 140123.83

Sheet FAR23
A1: FAR MRC Management Services
A3: Ledger Accounts: MARCH 2022 - FEBRUARY 2023
A4: Date | B4: Reference | C4: Description | D4: Cost (ExVAT) | E4: Additions | F4: Disp | G4: Total | H4: Per | I4: 44651 | J4: 44681 | K4: 44712 | L4: 44742 | M4: 44773 | N4: 44804 | O4: 44834 | P4: 44865 | Q4: 44895 | R4: 44926 | S4: 44957 | T4: 44985 | U4: Depn for Year | V4: Accum Depn | W4: NBV 2022
A6: 6100>020 (Computer Equipment>Cost) | I6: =+A6 -> 6100>020 (Computer Equipment>Cost)
H7: 3
A8: 42825 | B8: 18431 | C8: SevenC - 2 X HP Desktop CPU (AP & EM) | D8: ='FAR21'!G8 -> 16077.6 | G8: =+D8+E8-F8 -> 16077.6 | I8: 0 | J8: 0 | K8: 0 | L8: 0 | M8: 0 | N8: 0 | O8: 0 | P8: 0 | Q8: 0 | R8: 0 | S8: 0 | T8: 0 | U8: =SUM(I8:T8) -> 0 | V8: ='FAR21'!V8+U8 -> 16077.6 | W8: =+G8-V8 -> 0
A9: 42825 | B9: 18431 | C9: SevenC - HP ProBook 450 G4 Laptop (JN) | D9: ='FAR21'!G9 -> 10078.8 | G9: =+D9+E9-F9 -> 10078.8 | I9: 0 | J9: 0 | K9: 0 | L9: 0 | M9: 0 | N9: 0 | O9: 0 | P9: 0 | Q9: 0 | R9: 0 | S9: 0 | T9: 0 | U9: =SUM(I9:T9) -> 0 | V9: ='FAR21'!V9+U9 -> 10078.8 | W9: =+G9-V9 -> 0
A10: 43046 | B10: INA90085 | C10: Heart FM - CBA/Polycom System / VC | D10: ='FAR21'!G10 -> 52651 | G10: =+D10+E10-F10 -> 52651 | I10: 0 | J10: 0 | K10: 0 | L10: 0 | M10: 0 | N10: 0 | O10: 0 | P10: 0 | Q10: 0 | R10: 0 | S10: 0 | T10: 0 | U10: =SUM(I10:T10) -> 0 | V10: ='FAR21'!V10+U10 -> 52651.004 | W10: =+G10-V10 -> -0.0036377473
A11: 43160 | B11: 21643 | C11: SevenC - 6 X HP Desktop & Keyboards | D11: ='FAR21'!G11 -> 92322.7 | G11: =+D11+E11-F11 -> 92322.7 | I11: 0 | J11: 0 | K11: 0 | L11: 0 | M11: 0 | N11: 0 | O11: 0 | P11: 0 | Q11: 0 | R11: 0 | S11: 0 | T11: 0 | U11: =SUM(I11:T11) -> 0 | V11: ='FAR21'!V11+U11 -> 92322.7 | W11: =+G11-V11 -> 0
A12: 44144 | B12: INV33588 | C12: SevenC - Server: Dell PowerEdge R440 | D12: ='FAR21'!G12 -> 92565.27 | G12: =+D12+E12-F12 -> 92565.27 | I12: =+$G12/$H$7/12 -> 2571.2575 | J12: =+$G12/$H$7/12 -> 2571.2575 | K12: =+$G12/$H$7/12 -> 2571.2575 | L12: =+$G12/$H$7/12 -> 2571.2575 | M12: =+$G12/$H$7/12 -> 2571.2575 | N12: =+$G12/$H$7/12 -> 2571.2575 | O12: =+$G12/$H$7/12 -> 2571.2575 | P12: =+$G12/$H$7/12 -> 2571.2575 | ... T12: =+$G12/$H$7/12 -> 2571.2575 | U12: =SUM(I12:T12) -> 30855.09 | V12: ='FAR22'!V12+U12 -> 61710.18 | W12: =+G12-V12 -> 30855.09
A13: (Brought to used in March 21)
D14: =SUM(D6:D13) -> 263695.37 | E14: =SUM(E6:E13) -> 0 | G14: =SUM(G8:G13) -> 263695.37 | I14: =SUM(I8:I13) -> 2571.2575 | J14: =SUM(J8:J13) -> 2571.2575 | K14: =SUM(K8:K13) -> 2571.2575 | L14: =SUM(L8:L13) -> 2571.2575 | M14: =SUM(M8:M13) -> 2571.2575 | N14: =SUM(N8:N13) -> 2571.2575 | O14: =SUM(O8:O13) -> 2571.2575 | P14: =SUM(P8:P13) -> 2571.2575 | ... W14: =SUM(W8:W13) -> 30855.086
A16: Date | B16: Reference | C16: Description | D16: Cost | E16: Additions | F16: Disp | G16: Total | H16: Per | I16: 44651 | J16: 44681 | K16: 44712 | L16: 44742 | M16: 44773 | N16: 44804 | O16: 44834 | P16: 44865 | Q16: 44895 | R16: 44926 | S16: 44957 | T16: 44985 | U16: Depn for Year | V16: Accum Depn | W16: NBV 2022
A17: 6200>020 (Furniture & Fittings>Cost) | H17: 6 | I17: =+A17 -> 6200>020 (Furniture & Fittings>Cost)
A19: 42836 | B19: 30110 | C19: BFS - 15 X Roberto High Back Chairs | D19: ='FAR21'!G19 -> 52250 | G19: =+D19+E19-F19 -> 52250 | I19: =+$G19/$H$17/12 -> 725.69444 | J19: =+$G19/$H$17/12 -> 725.69444 | K19: =+$G19/$H$17/12 -> 725.69444 | L19: =+$G19/$H$17/12 -> 725.69444 | M19: =+$G19/$H$17/12 -> 725.69444 | N19: =+$G19/$H$17/12 -> 725.69444 | O19: =+$G19/$H$17/12 -> 725.69444 | P19: =+$G19/$H$17/12 -> 725.69444 | ... T19: =+$G19/$H$17/12 -> 725.69444 | U19: =SUM(I19:T19) -> 8708.3333 | V19: ='FAR22'!V19+U19 -> 51251.922 | W19: =+G19-V19 -> 998.07839
A20: 43165 | B20: Piyox-TV | C20: Boardroom TV - Samsung 75" UHD | D20: ='FAR21'!G20 -> 44144 | G20: =+D20+E20-F20 -> 44144 | I20: =+$G20/$H$17/12 -> 613.11111 | J20: =+$G20/$H$17/12 -> 613.11111 | K20: =+$G20/$H$17/12 -> 613.11111 | L20: =+$G20/$H$17/12 -> 613.11111 | M20: =+$G20/$H$17/12 -> 613.11111 | N20: =+$G20/$H$17/12 -> 613.11111 | O20: =+$G20/$H$17/12 -> 613.11111 | P20: =+$G20/$H$17/12 -> 613.11111 | ... T20: =+$G20/$H$17/12 -> 613.11111 | U20: =SUM(I20:T20) -> 7357.3333 | V20: ='FAR22'!V20+U20 -> 36677.482 | W20: =+G20-V20 -> 7466.5175
A21: 43179 | B21: 32006 | C21: BFS - 5 X Roberto High Back Chairs | D21: ='FAR21'!G21 -> 19430 | G21: =+D21+E21-F21 -> 19430 | I21: =+$G21/$H$17/12 -> 269.86111 | J21: =+$G21/$H$17/12 -> 269.86111 | K21: =+$G21/$H$17/12 -> 269.86111 | L21: =+$G21/$H$17/12 -> 269.86111 | M21: =+$G21/$H$17/12 -> 269.86111 | N21: =+$G21/$H$17/12 -> 269.86111 | O21: =+$G21/$H$17/12 -> 269.86111 | P21: =+$G21/$H$17/12 -> 269.86111 | ... T21: =+$G21/$H$17/12 -> 269.86111 | U21: =SUM(I21:T21) -> 3238.3333 | V21: ='FAR22'!V21+U21 -> 16019.399 | W21: =+G21-V21 -> 3410.6008
A22: 43578 | B22: INV00651 | C22: C & D Design - Boardroom Table | D22: ='FAR21'!G22 -> 26544 | G22: =+D22+E22-F22 -> 26544 | I22: =+$G22/$H$17/12 -> 368.66667 | J22: =+$G22/$H$17/12 -> 368.66667 | K22: =+$G22/$H$17/12 -> 368.66667 | L22: =+$G22/$H$17/12 -> 368.66667 | M22: =+$G22/$H$17/12 -> 368.66667 | N22: =+$G22/$H$17/12 -> 368.66667 | O22: =+$G22/$H$17/12 -> 368.66667 | P22: =+$G22/$H$17/12 -> 368.66667 | ... T22: =+$G22/$H$17/12 -> 368.66667 | U22: =SUM(I22:T22) -> 4424 | V22: ='FAR22'!V22+U22 -> 17043.511 | W22: =+G22-V22 -> 9500.4895
A23: 43710 | B23: 34825 | C23: BFS - 4 X Roberto High Back Chairs | D23: ='FAR21'!G23 -> 15767 | G23: =+D23+E23-F23 -> 15767 | I23: =+$G23/$H$17/12 -> 218.98611 | J23: =+$G23/$H$17/12 -> 218.98611 | K23: =+$G23/$H$17/12 -> 218.98611 | L23: =+$G23/$H$17/12 -> 218.98611 | M23: =+$G23/$H$17/12 -> 218.98611 | N23: =+$G23/$H$17/12 -> 218.98611 | O23: =+$G23/$H$17/12 -> 218.98611 | P23: =+$G23/$H$17/12 -> 218.98611 | ... T23: =+$G23/$H$17/12 -> 218.98611 | U23: =SUM(I23:T23) -> 2627.8333 | V23: ='FAR22'!V23+U23 -> 9197.4167 | W23: =+G23-V23 -> 6569.5833
A24: 43710 | B24: 34825 | C24: BFS - 10 X Pasquale Visitors Arm Chairs | D24: ='FAR21'!G24 -> 25647 | G24: =+D24+E24-F24 -> 25647 | I24: =+$G24/$H$17/12 -> 356.20833 | J24: =+$G24/$H$17/12 -> 356.20833 | K24: =+$G24/$H$17/12 -> 356.20833 | L24: =+$G24/$H$17/12 -> 356.20833 | M24: =+$G24/$H$17/12 -> 356.20833 | N24: =+$G24/$H$17/12 -> 356.20833 | O24: =+$G24/$H$17/12 -> 356.20833 | P24: =+$G24/$H$17/12 -> 356.20833 | ... T24: =+$G24/$H$17/12 -> 356.20833 | U24: =SUM(I24:T24) -> 4274.5 | V24: ='FAR22'!V24+U24 -> 14960.75 | W24: =+G24-V24 -> 10686.25
A25: 44791 | B25: Piyox-TV | C25: Samsung 55" TV - Crystal UHD Smart TV | D25: 13715 | G25: 13715 | I25: 0 | J25: 0 | K25: 0 | L25: 0 | M25: 0 | N25: =+$G25/$H$17/365*(31-18) -> 81.413242 | O25: =+$G25/$H$17/12 -> 190.48611 | P25: =+$G25/$H$17/12 -> 190.48611 | Q25: =+$G25/$H$17/12 -> 190.48611 | R25: =+$G25/$H$17/12 -> 190.48611 | S25: =+$G25/$H$17/12 -> 190.48611 | T25: =+$G25/$H$17/12 -> 190.48611 | U25: =SUM(I25:T25) -> 1224.3299 | V25: =+U25 -> 1224.3299 | W25: =G25-V25 -> 12490.67
D27: =SUM(D17:D26) -> 197497 | E27: =SUM(E17:E26) -> 0 | F27: =SUM(F17:F24) -> 0 | G27: =SUM(D27:F27) -> 197497 | I27: =SUM(I19:I26) -> 2552.5278 | J27: =SUM(J19:J26) -> 2552.5278 | K27: =SUM(K19:K26) -> 2552.5278 | L27: =SUM(L19:L26) -> 2552.5278 | M27: =SUM(M19:M26) -> 2552.5278 | N27: =SUM(N19:N26) -> 2633.941 | O27: =SUM(O19:O26) -> 2743.0139 | P27: =SUM(P19:P26) -> 2743.0139 | ... W27: =SUM(W19:W26) -> 51122.19
A29: Date | B29: Reference | C29: Description | D29: Cost | E29: Additions | F29: Disp | G29: Total | H29: Per | I29: 44651 | J29: 44681 | K29: 44712 | L29: 44742 | M29: 44773 | N29: 44804 | O29: 44834 | P29: 44865 | Q29: 44895 | R29: 44926 | S29: 44957 | T29: 44985 | U29: Depn for Year | V29: Accum Depn | W29: NBV 2022
A30: 6300>020 (Motor Vehicles>Cost) | H30: 5 | I30: =+A30 -> 6300>020 (Motor Vehicles>Cost)
A32: 42860 | B32: 89009640 | C32: Rivonia Toyota: Corolla Quest 1.6 AT | D32: ='FAR21'!G31 -> 255969.92 | G32: =+D32+E32-F32 -> 255969.92 | I32: =+$G32/$H$30/12 -> 4266.1653 | J32: =+$G32/$H$30/12 -> 4266.1653 | K32: 619.47 | L32: 0 | M32: 0 | N32: 0 | O32: 0 | P32: 0 | Q32: 0 | R32: 0 | S32: 0 | T32: 0 | U32: =SUM(I32:T32) -> 9151.8007 | V32: =U32+'FAR22'!V31 -> 255969.92 | W32: =+G32-V32 -> 0.00058264844
D34: =SUM(D32) -> 255969.92 | E34: =SUM(E32) -> 0 | F34: =SUM(F32) -> 0 | G34: =SUM(D34:F34) -> 255969.92 | I34: =SUM(I32) -> 4266.1653 | J34: =SUM(J32) -> 4266.1653 | K34: =SUM(K32) -> 619.47 | L34: =SUM(L32) -> 0 | M34: =SUM(M32) -> 0 | N34: =SUM(N32) -> 0 | O34: =SUM(O32) -> 0 | P34: =SUM(P32) -> 0 | ... W34: =SUM(W32) -> 0.00058264844
A36: Grand Total | D36: =D14+D27+D34 -> 717162.29 | E36: =E14+E27+E34 -> 0 | F36: =F14+F27+F34 -> 0 | G36: =G14+G27+G34 -> 717162.29 | I36: =I14+I27+I34 -> 9389.9506 | J36: =J14+J27+J34 -> 9389.9506 | K36: =K14+K27+K34 -> 5743.2553 | L36: =L14+L27+L34 -> 5123.7853 | M36: =M14+M27+M34 -> 5123.7853 | N36: =N14+N27+N34 -> 5205.1985 | O36: =O14+O27+O34 -> 5314.2714 | P36: =P14+P27+P34 -> 5314.2714 | ... W36: =W14+W27+W34 -> 81977.277

Sheet FAR24
A1: FAR MRC Management Services
A3: Ledger Accounts: MARCH 2023 - FEBRUARY 2024
A4: Date | B4: Reference | C4: Description | D4: Cost (ExVAT) | E4: Additions | F4: Disp | G4: Total | H4: Per | I4: 45016 | J4: 45046 | K4: 45077 | L4: 45107 | M4: 45138 | N4: 45169 | O4: 45199 | P4: 45230 | Q4: 45260 | R4: 45291 | S4: 45322 | T4: 45351 | U4: Depn for Year | V4: Accum Depn | W4: NBV 2022
A6: 6100>020 (Computer Equipment>Cost) | I6: =+A6 -> 6100>020 (Computer Equipment>Cost)
H7: 3
A8: 42825 | B8: 18431 | C8: SevenC - 2 X HP Desktop CPU (AP & EM) | D8: ='FAR21'!G8 -> 16077.6 | G8: =+D8+E8-F8 -> 16077.6 | I8: 0 | J8: 0 | K8: 0 | L8: 0 | M8: 0 | N8: 0 | O8: 0 | P8: 0 | Q8: 0 | R8: 0 | S8: 0 | T8: 0 | U8: =SUM(I8:T8) -> 0 | V8: ='FAR21'!V8+U8 -> 16077.6 | W8: =+G8-V8 -> 0
A9: 42825 | B9: 18431 | C9: SevenC - HP ProBook 450 G4 Laptop (JN) | D9: ='FAR21'!G9 -> 10078.8 | G9: =+D9+E9-F9 -> 10078.8 | I9: 0 | J9: 0 | K9: 0 | L9: 0 | M9: 0 | N9: 0 | O9: 0 | P9: 0 | Q9: 0 | R9: 0 | S9: 0 | T9: 0 | U9: =SUM(I9:T9) -> 0 | V9: ='FAR21'!V9+U9 -> 10078.8 | W9: =+G9-V9 -> 0
A10: 43046 | B10: INA90085 | C10: Heart FM - CBA/Polycom System / VC | D10: ='FAR21'!G10 -> 52651 | G10: =+D10+E10-F10 -> 52651 | I10: 0 | J10: 0 | K10: 0 | L10: 0 | M10: 0 | N10: 0 | O10: 0 | P10: 0 | Q10: 0 | R10: 0 | S10: 0 | T10: 0 | U10: =SUM(I10:T10) -> 0 | V10: ='FAR21'!V10+U10 -> 52651.004 | W10: =+G10-V10 -> -0.0036377473
A11: 43160 | B11: 21643 | C11: SevenC - 6 X HP Desktop & Keyboards | D11: ='FAR21'!G11 -> 92322.7 | G11: =+D11+E11-F11 -> 92322.7 | I11: 0 | J11: 0 | K11: 0 | L11: 0 | M11: 0 | N11: 0 | O11: 0 | P11: 0 | Q11: 0 | R11: 0 | S11: 0 | T11: 0 | U11: =SUM(I11:T11) -> 0 | V11: ='FAR21'!V11+U11 -> 92322.7 | W11: =+G11-V11 -> 0
A12: 44144 | B12: INV33588 | C12: SevenC - Server: Dell PowerEdge R440 | D12: ='FAR21'!G12 -> 92565.27 | G12: =+D12+E12-F12 -> 92565.27 | I12: =+$G12/$H$7/12 -> 2571.2575 | J12: =+$G12/$H$7/12 -> 2571.2575 | K12: =+$G12/$H$7/12 -> 2571.2575 | L12: =+$G12/$H$7/12 -> 2571.2575 | M12: =+$G12/$H$7/12 -> 2571.2575 | N12: =+$G12/$H$7/12 -> 2571.2575 | O12: =+$G12/$H$7/12 -> 2571.2575 | P12: =+$G12/$H$7/12 -> 2571.2575 | ... T12: =+$G12/$H$7/12 -> 2571.2575 | U12: =SUM(I12:T12) -> 30855.09 | V12: ='FAR23'!V12+U12 -> 92565.27 | W12: =+G12-V12 -> 0
A13: 45020 | B13: INV45459 | C13: HP450 G8 CI5-1135G7 8GB 512GB 15.6 FHD UWWVA | E13: 12460.87 | G13: =E13 -> 12460.87 | I13: 0 | J13: =+$G13/$H$7/365*(30-4) -> 295.87454 | K13: =+$G13/$H$7/12 -> 346.13528 | L13: =+$G13/$H$7/12 -> 346.13528 | M13: =+$G13/$H$7/12 -> 346.13528 | N13: =+$G13/$H$7/12 -> 346.13528 | O13: =+$G13/$H$7/12 -> 346.13528 | P13: =+$G13/$H$7/12 -> 346.13528 | Q13: =+$G13/$H$7/12 -> 346.13528 | R13: =+$G13/$H$7/12 -> 346.13528 | ... T13: =+$G13/$H$7/12 -> 346.13528 | U13: =SUM(I13:T13) -> 3757.2273 | V13: =U13 -> 3757.2273 | W13: =+G13-V13 -> 8703.6427
A14: 45188 | B14: INV47999 | C14: Dell E2424HS 60.5cm, FHD VA LED Monitor | E14: 7307.41 | G14: =E14 -> 7307.41 | I14: 0 | J14: 0 | K14: 0 | L14: 0 | M14: 0 | N14: 0 | O14: =+$G14/$H$7/365*(30-19) -> 73.407772 | P14: =+$G14/$H$7/12 -> 202.98361 | Q14: =+$G14/$H$7/12 -> 202.98361 | R14: =+$G14/$H$7/12 -> 202.98361 | S14: =+$G14/$H$7/12 -> 202.98361 | T14: =+$G14/$H$7/12 -> 202.98361 | U14: =SUM(I14:T14) -> 1088.3258 | V14: =U14 -> 1088.3258 | W14: =+G14-V14 -> 6219.0842
A16: (Brought to used in March 21)
D17: =SUM(D6:D16) -> 263695.37 | E17: =SUM(E6:E16) -> 19768.28 | G17: =SUM(G8:G16) -> 283463.65 | I17: =SUM(I8:I16) -> 2571.2575 | J17: =SUM(J8:J16) -> 2867.132 | K17: =SUM(K8:K16) -> 2917.3928 | L17: =SUM(L8:L16) -> 2917.3928 | M17: =SUM(M8:M16) -> 2917.3928 | N17: =SUM(N8:N16) -> 2917.3928 | O17: =SUM(O8:O16) -> 2990.8005 | P17: =SUM(P8:P16) -> 3120.3764 | ... W17: =SUM(W8:W16) -> 14922.723
A19: Date | B19: Reference | C19: Description | D19: Cost | E19: Additions | F19: Disp | G19: Total | H19: Per | I19: 45016 | J19: 45046 | K19: 45077 | L19: 45107 | M19: 45138 | N19: 45169 | O19: 45199 | P19: 45230 | Q19: 45260 | R19: 45291 | S19: 45322 | T19: 45351 | U19: Depn for Year | V19: Accum Depn | W19: NBV 2022
A20: 6200>020 (Furniture & Fittings>Cost) | H20: 6 | I20: =+A20 -> 6200>020 (Furniture & Fittings>Cost)
A22: 42836 | B22: 30110 | C22: BFS - 15 X Roberto High Back Chairs | D22: ='FAR21'!G19 -> 52250 | G22: =+D22+E22-F22 -> 52250 | I22: =+$G22/$H$20/12 -> 725.69444 | J22: 272.38 | K22: 0 | L22: 0 | M22: 0 | N22: 0 | O22: 0 | P22: 0 | Q22: 0 | R22: 0 | S22: 0 | T22: 0 | U22: =SUM(I22:T22) -> 998.07444 | V22: ='FAR23'!V19+U22 -> 52249.996 | W22: =+G22-V22 -> 0.0039421613
A23: 43165 | B23: Piyox-TV | C23: Boardroom TV - Samsung 75" UHD | D23: ='FAR21'!G20 -> 44144 | G23: =+D23+E23-F23 -> 44144 | I23: =+$G23/$H$20/12 -> 613.11111 | J23: =+$G23/$H$20/12 -> 613.11111 | K23: =+$G23/$H$20/12 -> 613.11111 | L23: =+$G23/$H$20/12 -> 613.11111 | M23: =+$G23/$H$20/12 -> 613.11111 | N23: =+$G23/$H$20/12 -> 613.11111 | O23: =+$G23/$H$20/12 -> 613.11111 | P23: =+$G23/$H$20/12 -> 613.11111 | ... T23: =+$G23/$H$20/12 -> 613.11111 | U23: =SUM(I23:T23) -> 7357.3333 | V23: ='FAR23'!V20+U23 -> 44034.816 | W23: =+G23-V23 -> 109.18417
A24: 43179 | B24: 32006 | C24: BFS - 5 X Roberto High Back Chairs | D24: ='FAR21'!G21 -> 19430 | G24: =+D24+E24-F24 -> 19430 | I24: =+$G24/$H$20/12 -> 269.86111 | J24: =+$G24/$H$20/12 -> 269.86111 | K24: =+$G24/$H$20/12 -> 269.86111 | L24: =+$G24/$H$20/12 -> 269.86111 | M24: =+$G24/$H$20/12 -> 269.86111 | N24: =+$G24/$H$20/12 -> 269.86111 | O24: =+$G24/$H$20/12 -> 269.86111 | P24: =+$G24/$H$20/12 -> 269.86111 | ... T24: =+$G24/$H$20/12 -> 269.86111 | U24: =SUM(I24:T24) -> 3238.3333 | V24: ='FAR23'!V21+U24 -> 19257.732 | W24: =+G24-V24 -> 172.2675
A25: 43578 | B25: INV00651 | C25: C & D Design - Boardroom Table | D25: ='FAR21'!G22 -> 26544 | G25: =+D25+E25-F25 -> 26544 | I25: =+$G25/$H$20/12 -> 368.66667 | J25: =+$G25/$H$20/12 -> 368.66667 | K25: =+$G25/$H$20/12 -> 368.66667 | L25: =+$G25/$H$20/12 -> 368.66667 | M25: =+$G25/$H$20/12 -> 368.66667 | N25: =+$G25/$H$20/12 -> 368.66667 | O25: =+$G25/$H$20/12 -> 368.66667 | P25: =+$G25/$H$20/12 -> 368.66667 | ... T25: =+$G25/$H$20/12 -> 368.66667 | U25: =SUM(I25:T25) -> 4424 | V25: ='FAR23'!V22+U25 -> 21467.511 | W25: =+G25-V25 -> 5076.4895
A26: 43710 | B26: 34825 | C26: BFS - 4 X Roberto High Back Chairs | D26: ='FAR21'!G23 -> 15767 | G26: =+D26+E26-F26 -> 15767 | I26: =+$G26/$H$20/12 -> 218.98611 | J26: =+$G26/$H$20/12 -> 218.98611 | K26: =+$G26/$H$20/12 -> 218.98611 | L26: =+$G26/$H$20/12 -> 218.98611 | M26: =+$G26/$H$20/12 -> 218.98611 | N26: =+$G26/$H$20/12 -> 218.98611 | O26: =+$G26/$H$20/12 -> 218.98611 | P26: =+$G26/$H$20/12 -> 218.98611 | ... T26: =+$G26/$H$20/12 -> 218.98611 | U26: =SUM(I26:T26) -> 2627.8333 | V26: ='FAR23'!V23+U26 -> 11825.25 | W26: =+G26-V26 -> 3941.75
A27: 43710 | B27: 34825 | C27: BFS - 10 X Pasquale Visitors Arm Chairs | D27: ='FAR21'!G24 -> 25647 | G27: =+D27+E27-F27 -> 25647 | I27: =+$G27/$H$20/12 -> 356.20833 | J27: =+$G27/$H$20/12 -> 356.20833 | K27: =+$G27/$H$20/12 -> 356.20833 | L27: =+$G27/$H$20/12 -> 356.20833 | M27: =+$G27/$H$20/12 -> 356.20833 | N27: =+$G27/$H$20/12 -> 356.20833 | O27: =+$G27/$H$20/12 -> 356.20833 | P27: =+$G27/$H$20/12 -> 356.20833 | ... T27: =+$G27/$H$20/12 -> 356.20833 | U27: =SUM(I27:T27) -> 4274.5 | V27: ='FAR23'!V24+U27 -> 19235.25 | W27: =+G27-V27 -> 6411.75
A28: 44791 | B28: Piyox-TV | C28: Samsung 55" TV - Crystal UHD Smart TV | D28: 13715 | G28: 13715 | I28: =+$G28/$H$20/12 -> 190.48611 | J28: =+$G28/$H$20/12 -> 190.48611 | K28: =+$G28/$H$20/12 -> 190.48611 | L28: =+$G28/$H$20/12 -> 190.48611 | M28: =+$G28/$H$20/12 -> 190.48611 | N28: =+$G28/$H$20/12 -> 190.48611 | O28: =+$G28/$H$20/12 -> 190.48611 | P28: =+$G28/$H$20/12 -> 190.48611 | ... T28: =+$G28/$H$20/12 -> 190.48611 | U28: =SUM(I28:T28) -> 2285.8333 | V28: ='FAR23'!V25+U28 -> 3510.1632 | W28: =G28-V28 -> 10204.837
D30: =SUM(D20:D29) -> 197497 | E30: =SUM(E20:E29) -> 0 | F30: =SUM(F20:F27) -> 0 | G30: =SUM(D30:F30) -> 197497 | I30: =SUM(I22:I29) -> 2743.0139 | J30: =SUM(J22:J29) -> 2289.6994 | K30: =SUM(K22:K29) -> 2017.3194 | L30: =SUM(L22:L29) -> 2017.3194 | M30: =SUM(M22:M29) -> 2017.3194 | N30: =SUM(N22:N29) -> 2017.3194 | O30: =SUM(O22:O29) -> 2017.3194 | P30: =SUM(P22:P29) -> 2017.3194 | ... W30: =SUM(W22:W29) -> 25916.282
A32: Date | B32: Reference | C32: Description | D32: Cost | E32: Additions | F32: Disp | G32: Total | H32: Per | I32: 45016 | J32: 45046 | K32: 45077 | L32: 45107 | M32: 45138 | N32: 45169 | O32: 45199 | P32: 45230 | Q32: 45260 | R32: 45291 | S32: 45322 | T32: 45351 | U32: Depn for Year | V32: Accum Depn | W32: NBV 2022
A33: 6300>020 (Motor Vehicles>Cost) | H33: 5 | I33: =+A33 -> 6300>020 (Motor Vehicles>Cost)
A35: 42860 | B35: 89009640 | C35: Rivonia Toyota: Corolla Quest 1.6 AT | D35: ='FAR21'!G31 -> 255969.92 | G35: =+D35+E35-F35 -> 255969.92 | I35: 0 | J35: 0 | K35: 0 | L35: 0 | M35: 0 | N35: 0 | O35: 0 | P35: 0 | Q35: 0 | R35: 0 | S35: 0 | T35: 0 | U35: =SUM(I35:T35) -> 0 | V35: ='FAR23'!V32 -> 255969.92 | W35: =+G35-V35 -> 0.00058264844
D37: =SUM(D35) -> 255969.92 | E37: =SUM(E35) -> 0 | F37: =SUM(F35) -> 0 | G37: =SUM(D37:F37) -> 255969.92 | I37: =SUM(I35) -> 0 | J37: =SUM(J35) -> 0 | K37: =SUM(K35) -> 0 | L37: =SUM(L35) -> 0 | M37: =SUM(M35) -> 0 | N37: =SUM(N35) -> 0 | O37: =SUM(O35) -> 0 | P37: =SUM(P35) -> 0 | ... W37: =SUM(W35) -> 0.00058264844
A40: Date | B40: Reference | C40: Description | D40: Cost | E40: Additions | F40: Disp | G40: Total | H40: Per | I40: 45016 | J40: 45046 | K40: 45077 | L40: 45107 | M40: 45138 | N40: 45169 | O40: 45199 | P40: 45230 | Q40: 45260 | R40: 45291 | S40: 45322 | T40: 45351 | U40: Depn for Year | V40: Accum Depn | W40: NBV 2022
A41: 6400>020 (Office Equipment>Cost) | I41: =+A41 -> 6400>020 (Office Equipment>Cost)
H42: 6
A43: 45139 | B43: Boardroom Upgrade1 | C43: Boardroom: Yearlink Microsoft V/C (Speaker) | E43: 44100 | G43: 44100 | I43: 0 | J43: 0 | K43: 0 | L43: 0 | M43: 0 | N43: =+$G43/$H$42/12 -> 612.5 | O43: =+$G43/$H$42/12 -> 612.5 | P43: =+$G43/$H$42/12 -> 612.5 | Q43: =+$G43/$H$42/12 -> 612.5 | R43: =+$G43/$H$42/12 -> 612.5 | S43: =+$G43/$H$42/12 -> 612.5 | T43: =+$G43/$H$42/12 -> 612.5 | U43: =SUM(I43:T43) -> 4287.5 | V43: =U43 -> 4287.5 | W43: =G43-V43 -> 39812.5
E45: =SUM(E43:E44) -> 44100 | G45: =SUM(G43:G44) -> 44100 | I45: =SUM(I43:I44) -> 0 | J45: =SUM(J43:J44) -> 0 | K45: =SUM(K43:K44) -> 0 | L45: =SUM(L43:L44) -> 0 | M45: =SUM(M43:M44) -> 0 | N45: =SUM(N43:N44) -> 612.5 | O45: =SUM(O43:O44) -> 612.5 | P45: =SUM(P43:P44) -> 612.5 | ... T45: =SUM(T43:T44) -> 612.5
A47: Grand Total | D47: =D17+D30+D37 -> 717162.29 | E47: =E17+E30+E37+E45 -> 63868.28 | F47: =F17+F30+F37 -> 0 | G47: =G17+G30+G37+G45 -> 781030.57 | I47: =I17+I30+I37 -> 5314.2714 | J47: =J17+J30+J37 -> 5156.8315 | K47: =K17+K30+K37 -> 4934.7122 | L47: =L17+L30+L37 -> 4934.7122 | M47: =M17+M30+M37 -> 4934.7122 | N47: =N17+N30+N37+N45 -> 5547.2122 | O47: =O17+O30+O37+O45 -> 5620.62 | P47: =P17+P30+P37+P45 -> 5750.1958 | Q47: =Q17+Q30+Q37+Q45 -> 5750.1958 | R47: =R17+R30+R37+R45 -> 5750.1958 | S47: =S17+S30+S37+S45 -> 5750.1958 | T47: =T17+T30+T37+T45 -> 5750.1958 | U47: =U17+U30+U37 -> 60906.551 | V47: =V17+V30+V37 -> 696091.56 | W47: =W17+W30+W37 -> 40839.006

Sheet FAR25
A1: FAR MRC Management Services
A3: Ledger Accounts: MARCH 2023 - FEBRUARY 2024
A4: Date | B4: Reference | C4: Description | D4: Cost (ExVAT) | E4: Additions | F4: Disp | G4: Total | H4: Per | I4: 45382 | J4: 45412 | K4: 45443 | L4: 45473 | M4: 45504 | N4: 45535 | O4: 45565 | P4: 45596 | Q4: 45626 | R4: 45657 | S4: 45688 | T4: 45716 | U4: Depn for Year | V4: Accum Depn | W4: NBV 2024
A6: 6100>020 (Computer Equipment>Cost) | I6: =+A6 -> 6100>020 (Computer Equipment>Cost)
H7: 3
A8: 42825 | B8: 18431 | C8: SevenC - 2 X HP Desktop CPU (AP & EM) | D8: ='FAR21'!G8 -> 16077.6 | G8: =+D8+E8-F8 -> 16077.6 | I8: 0 | J8: 0 | K8: 0 | L8: 0 | M8: 0 | N8: 0 | O8: 0 | P8: 0 | Q8: 0 | R8: 0 | S8: 0 | T8: 0 | U8: =SUM(I8:T8) -> 0 | V8: ='FAR21'!V8+U8 -> 16077.6 | W8: =+G8-V8 -> 0
